<?xml version="1.0" encoding="utf-8"?>
<!-- This URDF was automatically created by SolidWorks to URDF Exporter! Originally created by
Stephen Brawner (brawner@gmail.com) 
     Commit Version: 1.6.0-4-g7f85cfe  Build Version: 1.6.7995.38578
     For more information, please see http://wiki.ros.org/sw_urdf_exporter -->
<robot name="keti_workcell_description">
	<link name="world" />
	<!-- <joint name="world_base_UR" type="fixed">
		<origin xyz="0 0 0.0135" rpy="0 0 0" />
		<parent link="world" />
		<child link="base_UR" />
		<axis xyz="0 0 0" />
	</joint> -->

	<!-- UR robot -->
	<!-- <link name="base_UR">
		<visual>
			<geometry>
				<mesh filename="package://keti_workcell_description/meshes/base1.STL" />
			</geometry>
			<material name="base_color">
				<color rgba="0.89 0.91 0.93 1" />
			</material>
		</visual>
	</link>
	<link name="UR_jig">
		<visual>
			<geometry>
				<mesh filename="package://keti_workcell_description/meshes/UR_jig.STL"/>
			</geometry>
			<material name="">
				<color rgba="0.69 0.71 0.83 1" />
			</material>
		</visual>
	</link>
	<joint name="base_UR_to_UR_jig" type="fixed">
		<origin xyz="-0.00017 0.04561 0.835" rpy="0 0 0"/>
		<parent link="base_UR"/>
		<child link="UR_jig"/>
		<axis xyz="0 0 0"/>
	</joint>
	<link name="base_link">
		<visual>
			<geometry>
			  <mesh filename="package://keti_workcell_description/meshes/UR10e/base_link.STL" />
			</geometry>
			<material name="">
			  <color rgba="0.792156862745098 0.819607843137255 0.933333333333333 1" />
			</material>
		</visual>
	</link>
	<link name="link1">
		<visual>
			<geometry>
				<mesh filename="package://keti_workcell_description/meshes/UR10e/link1.STL" />
			</geometry>
			<material name="">
				<color rgba="0.79216 0.81961 0.93333 1" />
			</material>
		</visual>
	</link>
	<link name="link2">
		<visual>
			<geometry>
				<mesh filename="package://keti_workcell_description/meshes/UR10e/link2.STL" />
			</geometry>
			<material name="">
				<color rgba="0.79216 0.81961 0.93333 1" />
			</material>
		</visual>
	</link>
	<link name="link3">
		<visual>
			<geometry>
				<mesh filename="package://keti_workcell_description/meshes/UR10e/link3.STL" />
			</geometry>
			<material name="">
				<color rgba="0.79216 0.81961 0.93333 1" />
			</material>
		</visual>
	</link>
	<link name="link4">
		<visual>
			<geometry>
				<mesh filename="package://keti_workcell_description/meshes/UR10e/link4.STL" />
			</geometry>
			<material name="">
				<color rgba="0.79216 0.81961 0.93333 1" />
			</material>
		</visual>
	</link>
	<link name="link5">
		<visual>
			<geometry>
				<mesh filename="package://keti_workcell_description/meshes/UR10e/link5.STL" />
			</geometry>
			<material name="">
				<color rgba="0.79216 0.81961 0.93333 1" />
			</material>
		</visual>
	</link>
	<link name="link6">
		<visual>
			<geometry>
				<mesh filename="package://keti_workcell_description/meshes/UR10e/link6.STL" />
			</geometry>
			<material name="">
				<color rgba="0.79216 0.81961 0.93333 1" />
			</material>
		</visual>
	</link>
	<joint name="UR_jig_to_UR10e" type="fixed">
		<origin xyz="0 0 0" rpy="0 0 3.1416"/>
		<parent link="UR_jig"/>
		<child link="base_link"/>
		<axis xyz="0 0 0"/>
	</joint>
	<joint name="q1" type="revolute">
		<origin xyz="0 0 0" rpy="0 0 0" />
		<parent link="base_link" />
		<child link="link1" />
		<axis xyz="0 0 1" />
		<limit lower="-3.14" upper="3.14" effort="100" velocity="10" />
	</joint>
	<joint name="q2" type="revolute">
		<origin xyz="0 0 0.1807" rpy="1.5708 1.5708 0" />
		<parent link="link1" />
		<child link="link2" />
		<axis xyz="0 0 1" />
		<limit lower="-3.14" upper="3.14" effort="100" velocity="10" />
	</joint>
	<joint name="q3" type="revolute">
		<origin xyz="-0.6127 0 0" rpy="0 0 0" />
		<parent link="link2" />
		<child link="link3" />
		<axis xyz="0 0 1" />
		<limit lower="-3.14" upper="3.14" effort="100" velocity="10" />
	</joint>
	<joint name="q4" type="revolute">
		<origin xyz="-0.57155 0 0" rpy="0 0 -1.5708" />
		<parent link="link3" />
		<child link="link4" />
		<axis xyz="0 0 1" />
		<limit lower="-3.14" upper="3.14" effort="100" velocity="10" />
	</joint>
	<joint name="q5" type="revolute">
		<origin xyz="0 0 0.17415" rpy="1.5708 0 0" />
		<parent link="link4" />
		<child link="link5" />
		<axis xyz="0 0 1" />
		<limit lower="-3.14" upper="3.14" effort="100" velocity="10" />
	</joint>
	<joint name="q6" type="revolute">
		<origin xyz="0 0 0.11985" rpy="-1.5708 0 0" />
		<parent link="link5" />
		<child link="link6" />
		<axis xyz="0 0 1" />
		<limit lower="-3.14" upper="3.14" effort="100" velocity="10" />
	</joint>
	<link name="tool_changer">
		<visual>
			<geometry>
				<mesh filename="package://keti_workcell_description/meshes/tool_changer.STL"/>
			</geometry>
			<material name="">
				<color rgba="0.2 0.6 0.4 1"/>
			</material>
		</visual>
	</link>
	<joint name="link6_to_tool_changer" type="fixed">
		<origin xyz="0 0 0.18255" rpy="0 0 0"/>
		<parent link="link6"/>
		<child link="tool_changer"/>
		<axis xyz="0 0 0"/>
	</joint>
	<link name="koras_2f">
		<visual>
			<geometry>
				<mesh filename="package://keti_workcell_description/meshes/koras_2f.STL"/>
			</geometry>
			<material name="koras_2f_color">
				<color rgba="0.6 0.5 0.9 1"/>
			</material>
		</visual>
	</link>
	<joint name="tool_changer_to_koras_2f" type="fixed">
		<origin xyz="0 0 0" rpy="0 0 0"/>
		<parent link="tool_changer"/>
		<child link="koras_2f"/>
		<axis xyz="0 0 0"/>
	</joint> -->


	
	<!-- additional axis & DENSO robot -->
	<link name="base_DENSO">
		<visual>
			<geometry>
				<mesh filename="package://keti_workcell_description/meshes/base1.STL"/>
			</geometry>
			<material name="base_color">
				<color rgba="0.89 0.91 0.93 1" />
			</material>
		</visual>
	</link>
	<joint name="world_to_base_DENSO" type="fixed">
		<origin xyz="-0.80034 0.81298 0" rpy="0 0 -1.5708"/>
		<parent link="world"/>
		<child link="base_DENSO"/>
		<axis xyz="0 0 0"/>
	</joint>
	<link name="add_axis_jig1">
		<visual>
			<geometry>
				<mesh filename="package://keti_workcell_description/meshes/add_axis_jig1.STL"/>
			</geometry>
			<material name="">
				<color rgba="0.69 0.71 0.83 1" />
			</material>
		</visual>
	</link>
	<joint name="base_DENSO_to_add_axis_jig1" type="fixed">
		<origin xyz="-0.02489 0.17061 0.8315" rpy="0 0 0"/>
		<parent link="base_DENSO"/>
		<child link="add_axis_jig1"/>
		<axis xyz="0 0 0"/>
	</joint>
	<link name="slider_base1">
		<visual>
			<geometry>
				<mesh filename="package://keti_workcell_description/meshes/slider_base.STL"/>
			</geometry>
			<material name="slider_base_color">
				<color rgba="0.5 0.5 0.5 1"/>
			</material>
		</visual>
	</link>
	<joint name="add_axis_jig1_to_slider_base1" type="fixed">
		<origin xyz="0.37507 0 0.05482" rpy="1.5709 0 -1.5709"/>
		<parent link="add_axis_jig1"/>
		<child link="slider_base1"/>
		<axis xyz="0 0 0"/>
	</joint>
	<link name="slider1">
		<visual>
			<geometry>
				<mesh filename="package://keti_workcell_description/meshes/slider.STL"/>	
			</geometry>
			<material name="">
				<color rgba="0.3 0.3 0.3 1"/>
			</material>
		</visual>
	</link>
	<joint name="s1" type="prismatic">
		<origin xyz="0 0 0" rpy="0 0 0"/>
		<parent link="slider_base1"/>
		<child link="slider1"/>
		<axis xyz="0 0 1"/>
		<limit lower="0.05" upper="0.45" effort="100" velocity="10" />
	</joint>
	<link name="add_axis_jig2">
		<visual>
			<geometry>
				<mesh filename="package://keti_workcell_description/meshes/add_axis_jig2.STL"/>
			</geometry>
			<material name="">
				<color rgba="0.69 0.71 0.83 1" />
			</material>
		</visual>
	</link>
	<joint name="slider1_to_add_axis_jig2" type="fixed">
		<origin xyz="0 0.05926 0.1" rpy="-1.5709 0 0"/>
		<parent link="slider1"/>
		<child link="add_axis_jig2"/>
		<axis xyz="0 0 0"/>
	</joint>
	<link name="slider_base2">
		<visual>
			<geometry>
				<mesh filename="package://keti_workcell_description/meshes/slider_base.STL"/>
			</geometry>
			<material name="slider_base_color"/>
		</visual>
	</link>
	<joint name="add_axis_jig2_to_slider_base2" type="fixed">
		<origin xyz="0.35 0 0.05482" rpy="1.5709 0 -1.5709"/>
		<parent link="add_axis_jig2"/>
		<child link="slider_base2"/>
		<axis xyz="0 0 0"/>
	</joint>
	<link name="slider2">
		<visual>
			<geometry>
				<mesh filename="package://keti_workcell_description/meshes/slider.STL"/>	
			</geometry>
			<material name="">
				<color rgba="0.3 0.3 0.3 1"/>
			</material>
		</visual>
	</link>
	<joint name="s2" type="prismatic">
		<origin xyz="0 0 0" rpy="0 0 0"/>
		<parent link="slider_base2"/>
		<child link="slider2"/>
		<axis xyz="0 0 1"/>
		<limit lower="0.05" upper="0.45" effort="100" velocity="10" />
	</joint>
	<link name="DENSO_jig">
		<visual>
			<geometry>
				<mesh filename="package://keti_workcell_description/meshes/DENSO_jig.STL"/>	
			</geometry>
			<material name="">
				<color rgba="0.69 0.71 0.83 1" />
			</material>
		</visual>
	</link>
	<joint name="slider2_to_DENSO_jig" type="fixed">
		<origin xyz="0 0.06276 0.1" rpy="-1.5709 0 0"/>
		<parent link="slider2"/>
		<child link="DENSO_jig"/>
		<axis xyz="0 0 0"/>
	</joint>
	<link name="d_link0">
		<visual>
			<geometry>
				<mesh filename="package://keti_workcell_description/meshes/DENSO/d_link0.STL" />
			</geometry>
			<material name="">
				<color rgba="0.79216 0.81961 0.93333 1" />
			</material>
		</visual>
	</link>
	<joint name="denso_jig_to_robot" type="fixed">
		<origin xyz="0 0 0" rpy="0 0 -1.5709"/>
		<parent link="DENSO_jig"/>
		<child link="d_link0"/>
		<axis xyz="0 0 0"/>
	</joint>
	<link name="d_link1">
		<visual>
			<geometry>
				<mesh filename="package://keti_workcell_description/meshes/DENSO/d_link1.STL" />
			</geometry>
			<material name="">
				<color rgba="0.79216 0.81961 0.93333 1" />
			</material>
		</visual>
	</link>
	<joint name="d_q1" type="revolute">
		<origin xyz="0 0 0.37011" rpy="0 0 0" />
		<parent link="d_link0" />
		<child link="d_link1" />
		<axis xyz="0 0 1" />
		<limit lower="-3.14" upper="3.14" effort="100" velocity="10" />
	</joint>
	<link name="d_link2">
		<visual>
			<geometry>
				<mesh filename="package://keti_workcell_description/meshes/DENSO/d_link2.STL" />
			</geometry>
			<material name="">
				<color rgba="0.792156862745098 0.819607843137255 0.933333333333333 1" />
			</material>
		</visual>
	</link>
	<joint name="d_q2" type="revolute">
		<origin xyz="0.325 0 0" rpy="0 0 0" />
		<parent link="d_link1" />
		<child link="d_link2" />
		<axis xyz="0 0 1" />
		<limit lower="-3.14" upper="3.14" effort="100" velocity="10" />
	</joint>
	<link name="d_link3">
		<visual>
			<geometry>
				<mesh filename="package://keti_workcell_description/meshes/DENSO/d_link3.STL" />
			</geometry>
			<material name="">
				<color rgba="0.79216 0.81961 0.93333 1" />
			</material>
		</visual>
	</link>
	<joint name="d_q3" type="prismatic">
		<origin xyz="0.225 0 0" rpy="3.1416 0 0" />
		<parent link="d_link2" />
		<child link="d_link3" />
		<axis xyz="0 0 1" />
		<limit lower="-0.206" upper="0.0" effort="100" velocity="10" />
	</joint>
	<link name="d_end"/>
	<joint name="d_q3_to_end" type="fixed">
		<origin xyz="0 0 0.32900" rpy="3.1416 0 0"/>
		<parent link="d_link3"/>
		<child link="d_end"/>
		<axis xyz="0 0 0"/>
	</joint>
	<link name="denso_tool_changer">
		<visual>
			<geometry>
				<mesh filename="package://keti_workcell_description/meshes/denso_tool_changer.STL"/>
			</geometry>
		</visual>
		<material name="">
			<color 	rgba="0.6587 0.128 0.778 1"/>
		</material>
	</link>
	<joint name="denso_end_to_tool_changer" type="fixed">
		<origin xyz="0 0 -0.001" rpy="0 0 0"/>
		<parent link="d_end"/>
		<child link="denso_tool_changer"/>
		<axis xyz="0 0 0"/>
	</joint>
	<link name="ATC">
		<visual>
			<geometry>
				<mesh filename="package://keti_workcell_description/meshes/ATC.STL"/>
			</geometry>
			<material name="ATC_color">
				<color rgba="0.0 0.5 0.6 1"/>
			</material>
		</visual>
	</link>
	<joint name="denso_tool_changer_to_ATC" type="fixed">
		<origin xyz="0 0 -0.06" rpy="3.1416 0 -1.5709"/>
		<parent link="denso_tool_changer"/>
		<child link="ATC"/>
		<axis xyz="0 0 0"/>
	</joint>


	<!-- ARF -->
	<link name="base_ARF">
		<visual>
			<geometry>
				<mesh filename="package://keti_workcell_description/meshes/base2.STL"/>
			</geometry>
			<material name="base_color"/>
		</visual>
	</link>
	<joint name="world_to_base_ARF" type="fixed">
		<origin xyz="-0.00026 0.80842 -0.0135" rpy="0 0 3.1416"/>
		<parent link="world"/>
		<child link="base_ARF"/>
		<axis xyz="0 0 0"/>
	</joint>
	<link name="ARF_jig">
		<visual>
			<geometry>
				<mesh filename="package://keti_workcell_description/meshes/ARF_jig.STL"/>
			</geometry>
			<material name="">
				<color rgba="0.69 0.71 0.83 1" />
			</material>
		</visual>
	</link>
	<joint name="base_ARF_to_ARF_jig" type="fixed">
		<origin xyz="-0.02392 0.03311 0.8335" rpy="0 0 -1.5709"/>
		<parent link="base_ARF"/>
		<child link="ARF_jig"/>
		<axis xyz="0 0 0"/>
	</joint>
	<link name="ARF_slider_base1">
		<visual>
			<geometry>
				<mesh filename="package://keti_workcell_description/meshes/ARF_slider_base1.STL"/>	
			</geometry>
			<material name="">
				<color rgba="0.1 0.5 0.8 1"/>
			</material>
		</visual>
	</link>
	<joint name="ARF_jig_to_slider_base1" type="fixed">
		<origin xyz="0.29294 -0.31 0.05514" rpy="-1.5709 0 0"/>
		<parent link="ARF_jig"/>
		<child link="ARF_slider_base1"/>
		<axis xyz="0 0 0"/>
	</joint>
	<link name="ARF_slider1">
		<visual>
			<geometry>
				<mesh filename="package://keti_workcell_description/meshes/ARF_slider1.STL"/>
			</geometry>
			<material name="">
				<color rgba="0.7 0.5 0.3 1"/>
			</material>
		</visual>
	</link>
	<joint name="s3" type="prismatic">
		<origin xyz="-0.03044 -0.02835 0.0" rpy="0 0 0"/>
		<parent link="ARF_slider_base1"/>
		<child link="ARF_slider1"/>
		<axis xyz="0 0 1"/>
		<limit lower="0.045" upper="0.445" effort="100" velocity="10" />
	</joint>
	<link name="s4_dummy"/>
	<joint name="ARF_slider1_s4_dummy" type="fixed">
		<origin xyz="-0.569 -0.06672 0.06" rpy="0 1.5709 0"/>
		<parent link="ARF_slider1"/>
		<child link="s4_dummy"/>
		<axis xyz="0 0 0"/>
	</joint>
	<link name="ARF_slider2">
		<visual>
			<geometry>
				<mesh filename="package://keti_workcell_description/meshes/ARF_slider2.STL"/>
			</geometry>
			<material name="">
				<color rgba="0.5 0.4 0.6 1"/>
			</material>
		</visual>
	</link>
	<joint name="s4" type="prismatic">
		<origin xyz="0 -0.03128 0" rpy="0 0 0"/>
		<parent link="s4_dummy"/>
		<child link="ARF_slider2"/>
		<axis xyz="0 0 1"/>
		<limit lower="0.055" upper="0.355" effort="100" velocity="10" />
	</joint>
	<link name="ARF_jig2">
		<visual>
			<geometry>
				<mesh filename="package://keti_workcell_description/meshes/ARF_jig2.STL"/>
			</geometry>
			<material name="">
				<color rgba="0.1 0.6 0.5 1"/>
			</material>
		</visual>
	</link>
	<joint name="ARF_slider2_jig2" type="fixed">
		<origin xyz="0 -0.01652 0.06" rpy="1.5709 -1.5709 0"/>
		<parent link="ARF_slider2"/>
		<child link="ARF_jig2"/>
		<axis xyz="0 0 0"/>
	</joint>
	<link name="obj1">
		<visual>
			<geometry>
				<mesh filename="package://keti_workcell_description/meshes/obj1.STL"/>
			</geometry>
			<material name="">
				<color rgba="0.57 0.57 0.57 1" />
			</material>
		</visual>
	</link>
	<link name="obj2">
		<visual>
			<geometry>
				<mesh filename="package://keti_workcell_description/meshes/obj2.STL"/>
			</geometry>
			<material name="">
				<color rgba="0.57 0.57 0.57 1" />
			</material>
		</visual>
	</link>
	<joint name="ARF_jig2_to_obj1" type="fixed">
		<origin xyz="-0.02828 0.085 0.073" rpy="0 0 -1.5709"/>
		<parent link="ARF_jig2"/>
		<child link="obj1"/>
	</joint>
	<joint name="ARF_jig2_to_obj2" type="fixed">
		<origin xyz="-0.01802 -0.085 0.073" rpy="0 0 -1.5709"/>
		<parent link="ARF_jig2"/>
		<child link="obj2"/>
	</joint>
	<link name="zimmer1">
		<visual>
			<geometry>
				<mesh filename="package://keti_workcell_description/meshes/zimmer.STL"/>
			</geometry>	
			<material name="zimmer_color">
				<color rgba="0.3 0.3 0.3 1"/>
			</material>
		</visual>
	</link>
	<link name="zimmer2">
		<visual>
			<geometry>
				<mesh filename="package://keti_workcell_description/meshes/zimmer.STL"/>
			</geometry>	
			<material name="zimmer_color"/>
		</visual>
	</link>
	<joint name="ARF_jig2_to_zimmer1" type="fixed">
		<origin xyz="0 0.085 0.0552" rpy="1.5709 0 0"/>
		<parent link="ARF_jig2"/>
		<child link="zimmer1"/>
		<axis xyz="0 0 0"/>
	</joint>
	<joint name="ARF_jig2_to_zimmer2" type="fixed">
		<origin xyz="0 -0.085 0.0552" rpy="1.5709 0 0"/>
		<parent link="ARF_jig2"/>
		<child link="zimmer2"/>
		<axis xyz="0 0 0"/>
	</joint>
	<link name="tooltip11">
		<visual>
			<geometry>
				<mesh filename="package://keti_workcell_description/meshes/tooltip.STL"/>
			</geometry>
			<material name="tooltip_color">
				<color rgba="0.8 0.8 0.8 1"/>
			</material>
		</visual>
	</link>
	<link name="tooltip12">
		<visual>
			<geometry>
				<mesh filename="package://keti_workcell_description/meshes/tooltip.STL"/>
			</geometry>
			<material name="tooltip_color">
				<color rgba="0.8 0.8 0.8 1"/>
			</material>
		</visual>
	</link>
	<link name="tooltip21">
		<visual>
			<geometry>
				<mesh filename="package://keti_workcell_description/meshes/tooltip.STL"/>
			</geometry>
			<material name="tooltip_color">
				<color rgba="0.8 0.8 0.8 1"/>
			</material>
		</visual>
	</link>
	<link name="tooltip22">
		<visual>
			<geometry>
				<mesh filename="package://keti_workcell_description/meshes/tooltip.STL"/>
			</geometry>
			<material name="tooltip_color">
				<color rgba="0.8 0.8 0.8 1"/>
			</material>
		</visual>
	</link>
	<joint name="s5" type="prismatic">
		<origin xyz="-0.00037 0.00443 -0.041" rpy="0 0 0"/>
		<parent link="zimmer1"/>
		<child link="tooltip11"/>
		<axis xyz="0 0 1"/>
		<limit lower="0.0" upper="0.04" effort="100" velocity="10" />
	</joint>
	<joint name="s6" type="prismatic">
		<origin xyz="-0.00037 0.00443 0.041" rpy="0 3.1416 0"/>
		<parent link="zimmer1"/>
		<child link="tooltip12"/>
		<axis xyz="0 0 1"/>
		<limit lower="0.0" upper="0.04" effort="100" velocity="10" />
	</joint>
	<joint name="s7" type="prismatic">
		<origin xyz="-0.00037 0.00443 -0.041" rpy="0 0 0"/>
		<parent link="zimmer2"/>
		<child link="tooltip21"/>
		<axis xyz="0 0 1"/>
		<limit lower="0.0" upper="0.04" effort="100" velocity="10" />
	</joint>
	<joint name="s8" type="prismatic">
		<origin xyz="-0.00037 0.00443 0.041" rpy="0 3.1416 0"/>
		<parent link="zimmer2"/>
		<child link="tooltip22"/>
		<axis xyz="0 0 1"/>
		<limit lower="0.0" upper="0.04" effort="100" velocity="10" />
	</joint>


	<!-- feeder & tools -->
	<link name="base_ETC">
		<visual>
			<geometry>
				<mesh filename="package://keti_workcell_description/meshes/base2.STL"/>
			</geometry>
			<material name="base_color"/>
		</visual>
	</link>
	<joint name="world_to_base_ETC" type="fixed">
		<origin xyz="-0.80481 0 -0.0135" rpy="0 0 0"/>
		<parent link="world"/>
		<child link="base_ETC"/>
		<axis xyz="0 0 0"/>
	</joint>
	<link name="feeder">
		<visual>
			<geometry>
				<mesh filename="package://keti_workcell_description/meshes/feeder.STL"/>
			</geometry>
			<material name="">
				<color rgba="0.29 0.61 0.93 1" />
			</material>
		</visual>
	</link>
	<joint name="base_ETC_to_feeder" type="fixed">
		<origin xyz="-0.24992 0.19561 0.8465" rpy="0 0 0"/>
		<parent link="base_ETC"/>
		<child link="feeder"/>
		<axis xyz="0 0 0"/>
	</joint>
	<link name="tool_stand">
		<visual>
			<geometry>
				<mesh filename="package://keti_workcell_description/meshes/tool_stand.STL"/>
			</geometry>
			<material name="">
				<color rgba="0.5 0.5 0.5 1"/>
			</material>
		</visual>
	</link>
	<joint name="base_ETC_to_tool_stand" type="fixed">
		<origin xyz="0.15008 0.14561 0.8465" rpy="0 0 -1.5708"/>
		<parent link="base_ETC"/>
		<child link="tool_stand"/>
		<axis xyz="0 0 0"/>
	</joint>
	<link name="koras_2f_stand">
		<visual>
			<geometry>
				<mesh filename="package://keti_workcell_description/meshes/koras_2f.STL"/>
			</geometry>
			<material name="koras_2f_color"/>
		</visual>
	</link>
	<joint name="tool_stand_to_koras_2f" type="fixed">
		<origin xyz="-0.12582 0 0.312" rpy="3.1416 0 1.5709"/>
		<parent link="tool_stand"/>
		<child link="koras_2f_stand"/>
		<axis xyz="0 0 0"/>
	</joint>
	<link name="KRVG_stand">
		<visual>
			<geometry>
				<mesh filename="package://keti_workcell_description/meshes/KRVG.STL"/>
			</geometry>
			<material name="">
				<color rgba="0.6 0.5 0.0 1"/>
			</material>
		</visual>
	</link>
	<joint name="tool_stand_to_KRVG" type="fixed">
		<origin xyz="-0.12582 -0.1525 0.3125" rpy="3.1416 0 1.5709"/>
		<parent link="tool_stand"/>
		<child link="KRVG_stand"/>
		<zxis xyz="0 0 0"/>
	</joint>
	<link name="ATC_stand">
		<visual>
			<geometry>
				<mesh filename="package://keti_workcell_description/meshes/ATC.STL"/>
			</geometry>
			<material name="ATC_color">
				<color rgba="0.0 0.5 0.6 1"/>
			</material>
		</visual>
	</link>
	<joint name="tool_stand_to_ATC" type="fixed">
		<origin xyz="-0.1258 0.1525 0.314" rpy="3.1416 0 1.5709"/>
		<parent link="tool_stand"/>
		<child link="ATC_stand"/>
		<axis xyz="0 0 0"/>
	</joint>
</robot>